<robot name = "robot">
    <link name="Torso">
        <inertial>
            <origin xyz="0 0 0.5" rpy="0 0 0"/>
            <mass value="1" />
            <inertia ixx="100" ixy="0" ixz="0" iyy="100" iyz="0" izz="100" />
        </inertial>
        <visual>
            <origin xyz="0 0 0.5" rpy="0 0 0"/>
            <geometry>
                <box size="0.865695383743746 0.7381951850266926 0.9008133971875887" />
            </geometry>
            <material name="green">
                <color rgba="0 1.0 0 1,0"/>
            </material>
        </visual>
        <collision>
            <origin xyz="0 0 0.5" rpy="0 0 0"/>
            <geometry>
                <box size="0.865695383743746 0.7381951850266926 0.9008133971875887" />
            </geometry>
        </collision>
    </link>
    <joint name="Torso_Block0" type="revolute">
       <parent link="Torso"/>
       <child  link="Block0"/>
       <origin rpy="0 0 0" xyz="0 0.3690975925133463 0.5" />
     <axis xyz="1 0 1"/>
       <limit effort="0.0" lower="-3.14159" upper="3.14159" velocity="0.0"/>
    </joint>
    <link name="Block0">
        <inertial>
            <origin xyz="0 0.32237891751820513 0" rpy="0 0 0"/>
            <mass value="1" />
            <inertia ixx="100" ixy="0" ixz="0" iyy="100" iyz="0" izz="100" />
        </inertial>
        <visual>
            <origin xyz="0 0.32237891751820513 0" rpy="0 0 0"/>
            <geometry>
                <box size="0.09518806501099673 0.6447578350364103 0.6864439534894834" />
            </geometry>
            <material name="Cyan">
                <color rgba="0 1.0 1.0 1.0"/>
            </material>
        </visual>
        <collision>
            <origin xyz="0 0.32237891751820513 0" rpy="0 0 0"/>
            <geometry>
                <box size="0.09518806501099673 0.6447578350364103 0.6864439534894834" />
            </geometry>
        </collision>
    </link>
    <joint name="Block0_Block1" type="revolute">
       <parent link="Block0"/>
       <child  link="Block1"/>
       <origin rpy="0 0 0" xyz="0 0.32237891751820513 0" />
     <axis xyz="0 0 1"/>
       <limit effort="0.0" lower="-3.14159" upper="3.14159" velocity="0.0"/>
    </joint>
    <link name="Block1">
        <inertial>
            <origin xyz="0 0.9847228526139108 0" rpy="0 0 0"/>
            <mass value="1" />
            <inertia ixx="100" ixy="0" ixz="0" iyy="100" iyz="0" izz="100" />
        </inertial>
        <visual>
            <origin xyz="0 0.9847228526139108 0" rpy="0 0 0"/>
            <geometry>
                <box size="0.8352738498040315 1.9694457052278216 0.3293386437176482" />
            </geometry>
            <material name="Cyan">
                <color rgba="0 1.0 1.0 1.0"/>
            </material>
        </visual>
        <collision>
            <origin xyz="0 0.9847228526139108 0" rpy="0 0 0"/>
            <geometry>
                <box size="0.8352738498040315 1.9694457052278216 0.3293386437176482" />
            </geometry>
        </collision>
    </link>
    <joint name="Block1_Block2" type="revolute">
       <parent link="Block1"/>
       <child  link="Block2"/>
       <origin rpy="0 0 0" xyz="0 0.9847228526139108 0" />
     <axis xyz="0 1 0"/>
       <limit effort="0.0" lower="-3.14159" upper="3.14159" velocity="0.0"/>
    </joint>
    <link name="Block2">
        <inertial>
            <origin xyz="0 0.8981816191039548 0" rpy="0 0 0"/>
            <mass value="1" />
            <inertia ixx="100" ixy="0" ixz="0" iyy="100" iyz="0" izz="100" />
        </inertial>
        <visual>
            <origin xyz="0 0.8981816191039548 0" rpy="0 0 0"/>
            <geometry>
                <box size="0.9981277725382486 1.7963632382079096 0.4388671660049912" />
            </geometry>
            <material name="Cyan">
                <color rgba="0 1.0 1.0 1.0"/>
            </material>
        </visual>
        <collision>
            <origin xyz="0 0.8981816191039548 0" rpy="0 0 0"/>
            <geometry>
                <box size="0.9981277725382486 1.7963632382079096 0.4388671660049912" />
            </geometry>
        </collision>
    </link>
    <joint name="Block2_Block3" type="revolute">
       <parent link="Block2"/>
       <child  link="Block3"/>
       <origin rpy="0 0 0" xyz="0.4990638862691243 0.8981816191039548 0" />
     <axis xyz="1 0 0"/>
       <limit effort="0.0" lower="-3.14159" upper="3.14159" velocity="0.0"/>
    </joint>
    <link name="Block3">
        <inertial>
            <origin xyz="0.41745185708351074 0 0" rpy="0 0 0"/>
            <mass value="1" />
            <inertia ixx="100" ixy="0" ixz="0" iyy="100" iyz="0" izz="100" />
        </inertial>
        <visual>
            <origin xyz="0.41745185708351074 0 0" rpy="0 0 0"/>
            <geometry>
                <box size="0.8349037141670215 1.5976571489956872 0.6531235882103946" />
            </geometry>
            <material name="Cyan">
                <color rgba="0 1.0 1.0 1.0"/>
            </material>
        </visual>
        <collision>
            <origin xyz="0.41745185708351074 0 0" rpy="0 0 0"/>
            <geometry>
                <box size="0.8349037141670215 1.5976571489956872 0.6531235882103946" />
            </geometry>
        </collision>
    </link>
    <joint name="Block3_Block4" type="revolute">
       <parent link="Block3"/>
       <child  link="Block4"/>
       <origin rpy="0 0 0" xyz="0.41745185708351074 0.7988285744978436 0" />
     <axis xyz="1 0 0"/>
       <limit effort="0.0" lower="-3.14159" upper="3.14159" velocity="0.0"/>
    </joint>
    <link name="Block4">
        <inertial>
            <origin xyz="0 0.803764399662742 0" rpy="0 0 0"/>
            <mass value="1" />
            <inertia ixx="100" ixy="0" ixz="0" iyy="100" iyz="0" izz="100" />
        </inertial>
        <visual>
            <origin xyz="0 0.803764399662742 0" rpy="0 0 0"/>
            <geometry>
                <box size="0.34744922478631257 1.607528799325484 0.4444150699679993" />
            </geometry>
            <material name="green">
                <color rgba="0 1.0 0 1,0"/>
            </material>
        </visual>
        <collision>
            <origin xyz="0 0.803764399662742 0" rpy="0 0 0"/>
            <geometry>
                <box size="0.34744922478631257 1.607528799325484 0.4444150699679993" />
            </geometry>
        </collision>
    </link>
    <joint name="Block4_Block5" type="revolute">
       <parent link="Block4"/>
       <child  link="Block5"/>
       <origin rpy="0 0 0" xyz="0.17372461239315629 0.803764399662742 0" />
     <axis xyz="1 0 0"/>
       <limit effort="0.0" lower="-3.14159" upper="3.14159" velocity="0.0"/>
    </joint>
    <link name="Block5">
        <inertial>
            <origin xyz="0.14054291764721616 0 0" rpy="0 0 0"/>
            <mass value="1" />
            <inertia ixx="100" ixy="0" ixz="0" iyy="100" iyz="0" izz="100" />
        </inertial>
        <visual>
            <origin xyz="0.14054291764721616 0 0" rpy="0 0 0"/>
            <geometry>
                <box size="0.2810858352944323 1.3949236008701267 0.4699922159807449" />
            </geometry>
            <material name="Cyan">
                <color rgba="0 1.0 1.0 1.0"/>
            </material>
        </visual>
        <collision>
            <origin xyz="0.14054291764721616 0 0" rpy="0 0 0"/>
            <geometry>
                <box size="0.2810858352944323 1.3949236008701267 0.4699922159807449" />
            </geometry>
        </collision>
    </link>
    <joint name="Block5_Block6" type="revolute">
       <parent link="Block5"/>
       <child  link="Block6"/>
       <origin rpy="0 0 0" xyz="0.14054291764721616 0 0.23499610799037246" />
     <axis xyz="1 1 0"/>
       <limit effort="0.0" lower="-3.14159" upper="3.14159" velocity="0.0"/>
    </joint>
    <link name="Block6">
        <inertial>
            <origin xyz="0 0 0.3461715575473081" rpy="0 0 0"/>
            <mass value="1" />
            <inertia ixx="100" ixy="0" ixz="0" iyy="100" iyz="0" izz="100" />
        </inertial>
        <visual>
            <origin xyz="0 0 0.3461715575473081" rpy="0 0 0"/>
            <geometry>
                <box size="0.5441139851441644 0.2556436218584428 0.6923431150946162" />
            </geometry>
            <material name="Cyan">
                <color rgba="0 1.0 1.0 1.0"/>
            </material>
        </visual>
        <collision>
            <origin xyz="0 0 0.3461715575473081" rpy="0 0 0"/>
            <geometry>
                <box size="0.5441139851441644 0.2556436218584428 0.6923431150946162" />
            </geometry>
        </collision>
    </link>
    <joint name="Block6_Block7" type="revolute">
       <parent link="Block6"/>
       <child  link="Block7"/>
       <origin rpy="0 0 0" xyz="0 0 0.6923431150946162" />
     <axis xyz="1 0 0"/>
       <limit effort="0.0" lower="-3.14159" upper="3.14159" velocity="0.0"/>
    </joint>
    <link name="Block7">
        <inertial>
            <origin xyz="0 0 0.21845864566993045" rpy="0 0 0"/>
            <mass value="1" />
            <inertia ixx="100" ixy="0" ixz="0" iyy="100" iyz="0" izz="100" />
        </inertial>
        <visual>
            <origin xyz="0 0 0.21845864566993045" rpy="0 0 0"/>
            <geometry>
                <box size="0.7975246701121648 1.0976053794638057 0.4369172913398609" />
            </geometry>
            <material name="green">
                <color rgba="0 1.0 0 1,0"/>
            </material>
        </visual>
        <collision>
            <origin xyz="0 0 0.21845864566993045" rpy="0 0 0"/>
            <geometry>
                <box size="0.7975246701121648 1.0976053794638057 0.4369172913398609" />
            </geometry>
        </collision>
    </link>
</robot>