<robot name = "robot">
    <link name="Torso">
        <inertial>
            <origin xyz="0 0 0.5" rpy="0 0 0"/>
            <mass value="1" />
            <inertia ixx="100" ixy="0" ixz="0" iyy="100" iyz="0" izz="100" />
        </inertial>
        <visual>
            <origin xyz="0 0 0.5" rpy="0 0 0"/>
            <geometry>
                <box size="0.7679544029403025 0.85114316166169 0.26891675029296336" />
            </geometry>
            <material name="green">
                <color rgba="0 1.0 0 1,0"/>
            </material>
        </visual>
        <collision>
            <origin xyz="0 0 0.5" rpy="0 0 0"/>
            <geometry>
                <box size="0.7679544029403025 0.85114316166169 0.26891675029296336" />
            </geometry>
        </collision>
    </link>
    <joint name="Torso_Block0" type="revolute">
       <parent link="Torso"/>
       <child  link="Block0"/>
       <origin rpy="0 0 0" xyz="0.38397720147015124 0 0.5" />
     <axis xyz="1 0 0"/>
       <limit effort="0.0" lower="-3.14159" upper="3.14159" velocity="0.0"/>
    </joint>
    <link name="Block0">
        <inertial>
            <origin xyz="0.20746706872520715 0 0" rpy="0 0 0"/>
            <mass value="1" />
            <inertia ixx="100" ixy="0" ixz="0" iyy="100" iyz="0" izz="100" />
        </inertial>
        <visual>
            <origin xyz="0.20746706872520715 0 0" rpy="0 0 0"/>
            <geometry>
                <box size="0.4149341374504143 1.5775971780695452 0.31331272607892746" />
            </geometry>
            <material name="Cyan">
                <color rgba="0 1.0 1.0 1.0"/>
            </material>
        </visual>
        <collision>
            <origin xyz="0.20746706872520715 0 0" rpy="0 0 0"/>
            <geometry>
                <box size="0.4149341374504143 1.5775971780695452 0.31331272607892746" />
            </geometry>
        </collision>
    </link>
    <joint name="Block0_Block1" type="revolute">
       <parent link="Block0"/>
       <child  link="Block1"/>
       <origin rpy="0 0 0" xyz="0.20746706872520715 0.7887985890347726 0" />
     <axis xyz="1 1 0"/>
       <limit effort="0.0" lower="-3.14159" upper="3.14159" velocity="0.0"/>
    </joint>
    <link name="Block1">
        <inertial>
            <origin xyz="0 0.2234427269152317 0" rpy="0 0 0"/>
            <mass value="1" />
            <inertia ixx="100" ixy="0" ixz="0" iyy="100" iyz="0" izz="100" />
        </inertial>
        <visual>
            <origin xyz="0 0.2234427269152317 0" rpy="0 0 0"/>
            <geometry>
                <box size="0.9016606598206824 0.4468854538304634 0.14927370519815264" />
            </geometry>
            <material name="Cyan">
                <color rgba="0 1.0 1.0 1.0"/>
            </material>
        </visual>
        <collision>
            <origin xyz="0 0.2234427269152317 0" rpy="0 0 0"/>
            <geometry>
                <box size="0.9016606598206824 0.4468854538304634 0.14927370519815264" />
            </geometry>
        </collision>
    </link>
    <joint name="Block1_Block2" type="revolute">
       <parent link="Block1"/>
       <child  link="Block2"/>
       <origin rpy="0 0 0" xyz="0 0.2234427269152317 0.07463685259907632" />
     <axis xyz="1 0 0"/>
       <limit effort="0.0" lower="-3.14159" upper="3.14159" velocity="0.0"/>
    </joint>
    <link name="Block2">
        <inertial>
            <origin xyz="0 0 0.2712818170442636" rpy="0 0 0"/>
            <mass value="1" />
            <inertia ixx="100" ixy="0" ixz="0" iyy="100" iyz="0" izz="100" />
        </inertial>
        <visual>
            <origin xyz="0 0 0.2712818170442636" rpy="0 0 0"/>
            <geometry>
                <box size="0.809402574081021 1.9845184020660258 0.5425636340885271" />
            </geometry>
            <material name="Cyan">
                <color rgba="0 1.0 1.0 1.0"/>
            </material>
        </visual>
        <collision>
            <origin xyz="0 0 0.2712818170442636" rpy="0 0 0"/>
            <geometry>
                <box size="0.809402574081021 1.9845184020660258 0.5425636340885271" />
            </geometry>
        </collision>
    </link>
    <joint name="Block2_Block3" type="revolute">
       <parent link="Block2"/>
       <child  link="Block3"/>
       <origin rpy="0 0 0" xyz="0 0 0.5425636340885271" />
     <axis xyz="1 0 0"/>
       <limit effort="0.0" lower="-3.14159" upper="3.14159" velocity="0.0"/>
    </joint>
    <link name="Block3">
        <inertial>
            <origin xyz="0 0 0.45441914398399674" rpy="0 0 0"/>
            <mass value="1" />
            <inertia ixx="100" ixy="0" ixz="0" iyy="100" iyz="0" izz="100" />
        </inertial>
        <visual>
            <origin xyz="0 0 0.45441914398399674" rpy="0 0 0"/>
            <geometry>
                <box size="0.32014756931933264 1.4696634965202573 0.9088382879679935" />
            </geometry>
            <material name="green">
                <color rgba="0 1.0 0 1,0"/>
            </material>
        </visual>
        <collision>
            <origin xyz="0 0 0.45441914398399674" rpy="0 0 0"/>
            <geometry>
                <box size="0.32014756931933264 1.4696634965202573 0.9088382879679935" />
            </geometry>
        </collision>
    </link>
    <joint name="Block3_Block4" type="revolute">
       <parent link="Block3"/>
       <child  link="Block4"/>
       <origin rpy="0 0 0" xyz="0 0 0.9088382879679935" />
     <axis xyz="1 0 0"/>
       <limit effort="0.0" lower="-3.14159" upper="3.14159" velocity="0.0"/>
    </joint>
    <link name="Block4">
        <inertial>
            <origin xyz="0 0 0.16309834976079673" rpy="0 0 0"/>
            <mass value="1" />
            <inertia ixx="100" ixy="0" ixz="0" iyy="100" iyz="0" izz="100" />
        </inertial>
        <visual>
            <origin xyz="0 0 0.16309834976079673" rpy="0 0 0"/>
            <geometry>
                <box size="0.5698136790149003 0.7175826590384815 0.32619669952159347" />
            </geometry>
            <material name="Cyan">
                <color rgba="0 1.0 1.0 1.0"/>
            </material>
        </visual>
        <collision>
            <origin xyz="0 0 0.16309834976079673" rpy="0 0 0"/>
            <geometry>
                <box size="0.5698136790149003 0.7175826590384815 0.32619669952159347" />
            </geometry>
        </collision>
    </link>
    <joint name="Block4_Block5" type="revolute">
       <parent link="Block4"/>
       <child  link="Block5"/>
       <origin rpy="0 0 0" xyz="0 0 0.32619669952159347" />
     <axis xyz="1 0 0"/>
       <limit effort="0.0" lower="-3.14159" upper="3.14159" velocity="0.0"/>
    </joint>
    <link name="Block5">
        <inertial>
            <origin xyz="0 0 0.1352461551959797" rpy="0 0 0"/>
            <mass value="1" />
            <inertia ixx="100" ixy="0" ixz="0" iyy="100" iyz="0" izz="100" />
        </inertial>
        <visual>
            <origin xyz="0 0 0.1352461551959797" rpy="0 0 0"/>
            <geometry>
                <box size="0.48700977655271704 1.7406198555432801 0.2704923103919594" />
            </geometry>
            <material name="green">
                <color rgba="0 1.0 0 1,0"/>
            </material>
        </visual>
        <collision>
            <origin xyz="0 0 0.1352461551959797" rpy="0 0 0"/>
            <geometry>
                <box size="0.48700977655271704 1.7406198555432801 0.2704923103919594" />
            </geometry>
        </collision>
    </link>
    <joint name="Block5_Block6" type="revolute">
       <parent link="Block5"/>
       <child  link="Block6"/>
       <origin rpy="0 0 0" xyz="0 0 0.2704923103919594" />
     <axis xyz="1 0 0"/>
       <limit effort="0.0" lower="-3.14159" upper="3.14159" velocity="0.0"/>
    </joint>
    <link name="Block6">
        <inertial>
            <origin xyz="0 0 0.4174224885741165" rpy="0 0 0"/>
            <mass value="1" />
            <inertia ixx="100" ixy="0" ixz="0" iyy="100" iyz="0" izz="100" />
        </inertial>
        <visual>
            <origin xyz="0 0 0.4174224885741165" rpy="0 0 0"/>
            <geometry>
                <box size="0.7297046864039541 0.8076470844485375 0.834844977148233" />
            </geometry>
            <material name="Cyan">
                <color rgba="0 1.0 1.0 1.0"/>
            </material>
        </visual>
        <collision>
            <origin xyz="0 0 0.4174224885741165" rpy="0 0 0"/>
            <geometry>
                <box size="0.7297046864039541 0.8076470844485375 0.834844977148233" />
            </geometry>
        </collision>
    </link>
    <joint name="Block6_Block7" type="revolute">
       <parent link="Block6"/>
       <child  link="Block7"/>
       <origin rpy="0 0 0" xyz="0.36485234320197707 0 0.4174224885741165" />
     <axis xyz="0 0 1"/>
       <limit effort="0.0" lower="-3.14159" upper="3.14159" velocity="0.0"/>
    </joint>
    <link name="Block7">
        <inertial>
            <origin xyz="0.2517889332326623 0 0" rpy="0 0 0"/>
            <mass value="1" />
            <inertia ixx="100" ixy="0" ixz="0" iyy="100" iyz="0" izz="100" />
        </inertial>
        <visual>
            <origin xyz="0.2517889332326623 0 0" rpy="0 0 0"/>
            <geometry>
                <box size="0.5035778664653247 1.7452055509855617 0.253910876887132" />
            </geometry>
            <material name="Cyan">
                <color rgba="0 1.0 1.0 1.0"/>
            </material>
        </visual>
        <collision>
            <origin xyz="0.2517889332326623 0 0" rpy="0 0 0"/>
            <geometry>
                <box size="0.5035778664653247 1.7452055509855617 0.253910876887132" />
            </geometry>
        </collision>
    </link>
    <joint name="Block7_Block8" type="revolute">
       <parent link="Block7"/>
       <child  link="Block8"/>
       <origin rpy="0 0 0" xyz="0.2517889332326623 0.8726027754927809 0" />
     <axis xyz="0 1 0"/>
       <limit effort="0.0" lower="-3.14159" upper="3.14159" velocity="0.0"/>
    </joint>
    <link name="Block8">
        <inertial>
            <origin xyz="0 0.22670389621418652 0" rpy="0 0 0"/>
            <mass value="1" />
            <inertia ixx="100" ixy="0" ixz="0" iyy="100" iyz="0" izz="100" />
        </inertial>
        <visual>
            <origin xyz="0 0.22670389621418652 0" rpy="0 0 0"/>
            <geometry>
                <box size="0.9270189691149499 0.45340779242837304 0.8133450541462023" />
            </geometry>
            <material name="green">
                <color rgba="0 1.0 0 1,0"/>
            </material>
        </visual>
        <collision>
            <origin xyz="0 0.22670389621418652 0" rpy="0 0 0"/>
            <geometry>
                <box size="0.9270189691149499 0.45340779242837304 0.8133450541462023" />
            </geometry>
        </collision>
    </link>
    <joint name="Block8_Block9" type="revolute">
       <parent link="Block8"/>
       <child  link="Block9"/>
       <origin rpy="0 0 0" xyz="0 0.22670389621418652 0" />
     <axis xyz="1 0 0"/>
       <limit effort="0.0" lower="-3.14159" upper="3.14159" velocity="0.0"/>
    </joint>
    <link name="Block9">
        <inertial>
            <origin xyz="0 0.5494074079316354 0" rpy="0 0 0"/>
            <mass value="1" />
            <inertia ixx="100" ixy="0" ixz="0" iyy="100" iyz="0" izz="100" />
        </inertial>
        <visual>
            <origin xyz="0 0.5494074079316354 0" rpy="0 0 0"/>
            <geometry>
                <box size="0.04870690221740647 1.098814815863271 0.8020127564137915" />
            </geometry>
            <material name="Cyan">
                <color rgba="0 1.0 1.0 1.0"/>
            </material>
        </visual>
        <collision>
            <origin xyz="0 0.5494074079316354 0" rpy="0 0 0"/>
            <geometry>
                <box size="0.04870690221740647 1.098814815863271 0.8020127564137915" />
            </geometry>
        </collision>
    </link>
    <joint name="Block9_Block10" type="revolute">
       <parent link="Block9"/>
       <child  link="Block10"/>
       <origin rpy="0 0 0" xyz="0 0.5494074079316354 0.4010063782068958" />
     <axis xyz="1 0 0"/>
       <limit effort="0.0" lower="-3.14159" upper="3.14159" velocity="0.0"/>
    </joint>
    <link name="Block10">
        <inertial>
            <origin xyz="0 0 0.10159600567137239" rpy="0 0 0"/>
            <mass value="1" />
            <inertia ixx="100" ixy="0" ixz="0" iyy="100" iyz="0" izz="100" />
        </inertial>
        <visual>
            <origin xyz="0 0 0.10159600567137239" rpy="0 0 0"/>
            <geometry>
                <box size="0.8059480275959208 0.7889159099697096 0.20319201134274478" />
            </geometry>
            <material name="Cyan">
                <color rgba="0 1.0 1.0 1.0"/>
            </material>
        </visual>
        <collision>
            <origin xyz="0 0 0.10159600567137239" rpy="0 0 0"/>
            <geometry>
                <box size="0.8059480275959208 0.7889159099697096 0.20319201134274478" />
            </geometry>
        </collision>
    </link>
</robot>