<robot name = "robot">
    <link name="Torso">
        <inertial>
            <origin xyz="0 0 0.5" rpy="0 0 0"/>
            <mass value="1" />
            <inertia ixx="100" ixy="0" ixz="0" iyy="100" iyz="0" izz="100" />
        </inertial>
        <visual>
            <origin xyz="0 0 0.5" rpy="0 0 0"/>
            <geometry>
                <box size="0.1073158679443844 1.2946269073718812 0.4156325875419097" />
            </geometry>
            <material name="Cyan">
                <color rgba="0 1.0 1.0 1.0"/>
            </material>
        </visual>
        <collision>
            <origin xyz="0 0 0.5" rpy="0 0 0"/>
            <geometry>
                <box size="0.1073158679443844 1.2946269073718812 0.4156325875419097" />
            </geometry>
        </collision>
    </link>
    <joint name="Torso_Block0" type="revolute">
       <parent link="Torso"/>
       <child  link="Block0"/>
       <origin rpy="0 0 0" xyz="0 0 0.7078162937709549" />
     <axis xyz="0 1 1"/>
       <limit effort="0.0" lower="-3.14159" upper="3.14159" velocity="0.0"/>
    </joint>
    <link name="Block0">
        <inertial>
            <origin xyz="0 0 0.3460663665809278" rpy="0 0 0"/>
            <mass value="1" />
            <inertia ixx="100" ixy="0" ixz="0" iyy="100" iyz="0" izz="100" />
        </inertial>
        <visual>
            <origin xyz="0 0 0.3460663665809278" rpy="0 0 0"/>
            <geometry>
                <box size="0.4190780359806797 0.8207202444995354 0.6921327331618556" />
            </geometry>
            <material name="Cyan">
                <color rgba="0 1.0 1.0 1.0"/>
            </material>
        </visual>
        <collision>
            <origin xyz="0 0 0.3460663665809278" rpy="0 0 0"/>
            <geometry>
                <box size="0.4190780359806797 0.8207202444995354 0.6921327331618556" />
            </geometry>
        </collision>
    </link>
    <joint name="Block0_Block1" type="revolute">
       <parent link="Block0"/>
       <child  link="Block1"/>
       <origin rpy="0 0 0" xyz="0 0 0.6921327331618556" />
     <axis xyz="0 1 1"/>
       <limit effort="0.0" lower="-3.14159" upper="3.14159" velocity="0.0"/>
    </joint>
    <link name="Block1">
        <inertial>
            <origin xyz="0 0 0.24378563258110958" rpy="0 0 0"/>
            <mass value="1" />
            <inertia ixx="100" ixy="0" ixz="0" iyy="100" iyz="0" izz="100" />
        </inertial>
        <visual>
            <origin xyz="0 0 0.24378563258110958" rpy="0 0 0"/>
            <geometry>
                <box size="0.7780375015433866 1.255400917802846 0.48757126516221916" />
            </geometry>
            <material name="green">
                <color rgba="0 1.0 0 1,0"/>
            </material>
        </visual>
        <collision>
            <origin xyz="0 0 0.24378563258110958" rpy="0 0 0"/>
            <geometry>
                <box size="0.7780375015433866 1.255400917802846 0.48757126516221916" />
            </geometry>
        </collision>
    </link>
    <joint name="Block1_Block2" type="revolute">
       <parent link="Block1"/>
       <child  link="Block2"/>
       <origin rpy="0 0 0" xyz="0.3890187507716933 0 0.24378563258110958" />
     <axis xyz="1 0 0"/>
       <limit effort="0.0" lower="-3.14159" upper="3.14159" velocity="0.0"/>
    </joint>
    <link name="Block2">
        <inertial>
            <origin xyz="0.2478684536241223 0 0" rpy="0 0 0"/>
            <mass value="1" />
            <inertia ixx="100" ixy="0" ixz="0" iyy="100" iyz="0" izz="100" />
        </inertial>
        <visual>
            <origin xyz="0.2478684536241223 0 0" rpy="0 0 0"/>
            <geometry>
                <box size="0.4957369072482446 1.657899018979481 0.7829427337528245" />
            </geometry>
            <material name="green">
                <color rgba="0 1.0 0 1,0"/>
            </material>
        </visual>
        <collision>
            <origin xyz="0.2478684536241223 0 0" rpy="0 0 0"/>
            <geometry>
                <box size="0.4957369072482446 1.657899018979481 0.7829427337528245" />
            </geometry>
        </collision>
    </link>
    <joint name="Block2_Block3" type="revolute">
       <parent link="Block2"/>
       <child  link="Block3"/>
       <origin rpy="0 0 0" xyz="0.2478684536241223 0 0.39147136687641226" />
     <axis xyz="1 0 0"/>
       <limit effort="0.0" lower="-3.14159" upper="3.14159" velocity="0.0"/>
    </joint>
    <link name="Block3">
        <inertial>
            <origin xyz="0 0 0.34466836472903" rpy="0 0 0"/>
            <mass value="1" />
            <inertia ixx="100" ixy="0" ixz="0" iyy="100" iyz="0" izz="100" />
        </inertial>
        <visual>
            <origin xyz="0 0 0.34466836472903" rpy="0 0 0"/>
            <geometry>
                <box size="0.6389988703492244 0.8964902893406168 0.68933672945806" />
            </geometry>
            <material name="green">
                <color rgba="0 1.0 0 1,0"/>
            </material>
        </visual>
        <collision>
            <origin xyz="0 0 0.34466836472903" rpy="0 0 0"/>
            <geometry>
                <box size="0.6389988703492244 0.8964902893406168 0.68933672945806" />
            </geometry>
        </collision>
    </link>
    <joint name="Block3_Block4" type="revolute">
       <parent link="Block3"/>
       <child  link="Block4"/>
       <origin rpy="0 0 0" xyz="0 0 0.68933672945806" />
     <axis xyz="1 0 0"/>
       <limit effort="0.0" lower="-3.14159" upper="3.14159" velocity="0.0"/>
    </joint>
    <link name="Block4">
        <inertial>
            <origin xyz="0 0 0.16155258403016715" rpy="0 0 0"/>
            <mass value="1" />
            <inertia ixx="100" ixy="0" ixz="0" iyy="100" iyz="0" izz="100" />
        </inertial>
        <visual>
            <origin xyz="0 0 0.16155258403016715" rpy="0 0 0"/>
            <geometry>
                <box size="0.6121993961111502 0.05403000421784742 0.3231051680603343" />
            </geometry>
            <material name="Cyan">
                <color rgba="0 1.0 1.0 1.0"/>
            </material>
        </visual>
        <collision>
            <origin xyz="0 0 0.16155258403016715" rpy="0 0 0"/>
            <geometry>
                <box size="0.6121993961111502 0.05403000421784742 0.3231051680603343" />
            </geometry>
        </collision>
    </link>
    <joint name="Block4_Block5" type="revolute">
       <parent link="Block4"/>
       <child  link="Block5"/>
       <origin rpy="0 0 0" xyz="0 0.02701500210892371 0.16155258403016715" />
     <axis xyz="0 1 1"/>
       <limit effort="0.0" lower="-3.14159" upper="3.14159" velocity="0.0"/>
    </joint>
    <link name="Block5">
        <inertial>
            <origin xyz="0 0.30400863507375986 0" rpy="0 0 0"/>
            <mass value="1" />
            <inertia ixx="100" ixy="0" ixz="0" iyy="100" iyz="0" izz="100" />
        </inertial>
        <visual>
            <origin xyz="0 0.30400863507375986 0" rpy="0 0 0"/>
            <geometry>
                <box size="0.5684501342949995 0.6080172701475197 0.6282333056987564" />
            </geometry>
            <material name="Cyan">
                <color rgba="0 1.0 1.0 1.0"/>
            </material>
        </visual>
        <collision>
            <origin xyz="0 0.30400863507375986 0" rpy="0 0 0"/>
            <geometry>
                <box size="0.5684501342949995 0.6080172701475197 0.6282333056987564" />
            </geometry>
        </collision>
    </link>
    <joint name="Block5_Block6" type="revolute">
       <parent link="Block5"/>
       <child  link="Block6"/>
       <origin rpy="0 0 0" xyz="0.28422506714749973 0.30400863507375986 0" />
     <axis xyz="0 1 0"/>
       <limit effort="0.0" lower="-3.14159" upper="3.14159" velocity="0.0"/>
    </joint>
    <link name="Block6">
        <inertial>
            <origin xyz="0.3760706851121862 0 0" rpy="0 0 0"/>
            <mass value="1" />
            <inertia ixx="100" ixy="0" ixz="0" iyy="100" iyz="0" izz="100" />
        </inertial>
        <visual>
            <origin xyz="0.3760706851121862 0 0" rpy="0 0 0"/>
            <geometry>
                <box size="0.7521413702243724 1.6234327920745801 0.21834090426791375" />
            </geometry>
            <material name="green">
                <color rgba="0 1.0 0 1,0"/>
            </material>
        </visual>
        <collision>
            <origin xyz="0.3760706851121862 0 0" rpy="0 0 0"/>
            <geometry>
                <box size="0.7521413702243724 1.6234327920745801 0.21834090426791375" />
            </geometry>
        </collision>
    </link>
    <joint name="Block6_Block7" type="revolute">
       <parent link="Block6"/>
       <child  link="Block7"/>
       <origin rpy="0 0 0" xyz="0.3760706851121862 0.8117163960372901 0" />
     <axis xyz="1 0 0"/>
       <limit effort="0.0" lower="-3.14159" upper="3.14159" velocity="0.0"/>
    </joint>
    <link name="Block7">
        <inertial>
            <origin xyz="0 0.20849647380167413 0" rpy="0 0 0"/>
            <mass value="1" />
            <inertia ixx="100" ixy="0" ixz="0" iyy="100" iyz="0" izz="100" />
        </inertial>
        <visual>
            <origin xyz="0 0.20849647380167413 0" rpy="0 0 0"/>
            <geometry>
                <box size="0.46583921093978264 0.41699294760334826 0.06159651661901266" />
            </geometry>
            <material name="green">
                <color rgba="0 1.0 0 1,0"/>
            </material>
        </visual>
        <collision>
            <origin xyz="0 0.20849647380167413 0" rpy="0 0 0"/>
            <geometry>
                <box size="0.46583921093978264 0.41699294760334826 0.06159651661901266" />
            </geometry>
        </collision>
    </link>
    <joint name="Block7_Block8" type="revolute">
       <parent link="Block7"/>
       <child  link="Block8"/>
       <origin rpy="0 0 0" xyz="0.23291960546989132 0.20849647380167413 0" />
     <axis xyz="0 1 1"/>
       <limit effort="0.0" lower="-3.14159" upper="3.14159" velocity="0.0"/>
    </joint>
    <link name="Block8">
        <inertial>
            <origin xyz="0.3520479373889334 0 0" rpy="0 0 0"/>
            <mass value="1" />
            <inertia ixx="100" ixy="0" ixz="0" iyy="100" iyz="0" izz="100" />
        </inertial>
        <visual>
            <origin xyz="0.3520479373889334 0 0" rpy="0 0 0"/>
            <geometry>
                <box size="0.7040958747778668 1.4724072735853098 0.139301070010451" />
            </geometry>
            <material name="green">
                <color rgba="0 1.0 0 1,0"/>
            </material>
        </visual>
        <collision>
            <origin xyz="0.3520479373889334 0 0" rpy="0 0 0"/>
            <geometry>
                <box size="0.7040958747778668 1.4724072735853098 0.139301070010451" />
            </geometry>
        </collision>
    </link>
    <joint name="Block8_Block9" type="revolute">
       <parent link="Block8"/>
       <child  link="Block9"/>
       <origin rpy="0 0 0" xyz="0.3520479373889334 0.7362036367926549 0" />
     <axis xyz="1 0 0"/>
       <limit effort="0.0" lower="-3.14159" upper="3.14159" velocity="0.0"/>
    </joint>
    <link name="Block9">
        <inertial>
            <origin xyz="0 0.3124008242658797 0" rpy="0 0 0"/>
            <mass value="1" />
            <inertia ixx="100" ixy="0" ixz="0" iyy="100" iyz="0" izz="100" />
        </inertial>
        <visual>
            <origin xyz="0 0.3124008242658797 0" rpy="0 0 0"/>
            <geometry>
                <box size="0.8072980786400239 0.6248016485317593 0.46282547203959357" />
            </geometry>
            <material name="Cyan">
                <color rgba="0 1.0 1.0 1.0"/>
            </material>
        </visual>
        <collision>
            <origin xyz="0 0.3124008242658797 0" rpy="0 0 0"/>
            <geometry>
                <box size="0.8072980786400239 0.6248016485317593 0.46282547203959357" />
            </geometry>
        </collision>
    </link>
    <joint name="Block9_Block10" type="revolute">
       <parent link="Block9"/>
       <child  link="Block10"/>
       <origin rpy="0 0 0" xyz="0.40364903932001195 0.3124008242658797 0" />
     <axis xyz="1 0 0"/>
       <limit effort="0.0" lower="-3.14159" upper="3.14159" velocity="0.0"/>
    </joint>
    <link name="Block10">
        <inertial>
            <origin xyz="0.47489645751992277 0 0" rpy="0 0 0"/>
            <mass value="1" />
            <inertia ixx="100" ixy="0" ixz="0" iyy="100" iyz="0" izz="100" />
        </inertial>
        <visual>
            <origin xyz="0.47489645751992277 0 0" rpy="0 0 0"/>
            <geometry>
                <box size="0.9497929150398455 1.8135610651652274 0.6358009528660449" />
            </geometry>
            <material name="Cyan">
                <color rgba="0 1.0 1.0 1.0"/>
            </material>
        </visual>
        <collision>
            <origin xyz="0.47489645751992277 0 0" rpy="0 0 0"/>
            <geometry>
                <box size="0.9497929150398455 1.8135610651652274 0.6358009528660449" />
            </geometry>
        </collision>
    </link>
    <joint name="Block10_Block11" type="revolute">
       <parent link="Block10"/>
       <child  link="Block11"/>
       <origin rpy="0 0 0" xyz="0.47489645751992277 0.9067805325826137 0" />
     <axis xyz="1 1 0"/>
       <limit effort="0.0" lower="-3.14159" upper="3.14159" velocity="0.0"/>
    </joint>
    <link name="Block11">
        <inertial>
            <origin xyz="0 0.5776354679901433 0" rpy="0 0 0"/>
            <mass value="1" />
            <inertia ixx="100" ixy="0" ixz="0" iyy="100" iyz="0" izz="100" />
        </inertial>
        <visual>
            <origin xyz="0 0.5776354679901433 0" rpy="0 0 0"/>
            <geometry>
                <box size="0.8443604572838727 1.1552709359802866 0.4678546803930441" />
            </geometry>
            <material name="Cyan">
                <color rgba="0 1.0 1.0 1.0"/>
            </material>
        </visual>
        <collision>
            <origin xyz="0 0.5776354679901433 0" rpy="0 0 0"/>
            <geometry>
                <box size="0.8443604572838727 1.1552709359802866 0.4678546803930441" />
            </geometry>
        </collision>
    </link>
    <joint name="Block11_Block12" type="revolute">
       <parent link="Block11"/>
       <child  link="Block12"/>
       <origin rpy="0 0 0" xyz="0.42218022864193633 0.5776354679901433 0" />
     <axis xyz="1 0 0"/>
       <limit effort="0.0" lower="-3.14159" upper="3.14159" velocity="0.0"/>
    </joint>
    <link name="Block12">
        <inertial>
            <origin xyz="0.26400514153182525 0 0" rpy="0 0 0"/>
            <mass value="1" />
            <inertia ixx="100" ixy="0" ixz="0" iyy="100" iyz="0" izz="100" />
        </inertial>
        <visual>
            <origin xyz="0.26400514153182525 0 0" rpy="0 0 0"/>
            <geometry>
                <box size="0.5280102830636505 0.9917974327515109 0.9882679407426508" />
            </geometry>
            <material name="Cyan">
                <color rgba="0 1.0 1.0 1.0"/>
            </material>
        </visual>
        <collision>
            <origin xyz="0.26400514153182525 0 0" rpy="0 0 0"/>
            <geometry>
                <box size="0.5280102830636505 0.9917974327515109 0.9882679407426508" />
            </geometry>
        </collision>
    </link>
</robot>